Workbook

Sheet USE IND (A38) - ES (7)_ADJ
C1: Ecosystem services | D1: Crop provision | E1: Pollination | F1: Wood provision | G1: Air filtration | H1: Flood control | I1: Local climate regulation | J1: Nature based tourism | K1: Global climate regulation
C2: Unit | D2: 1000 tonnes | E2: 1000 tonnes | F2: 1000 m3 | G2: tonnes PM2,5 | H2: ha | I2: degrees C | J2: overnight stays | K2: tonnes of storage | L2: tonnes of sequestration
C3: Total | D3: ='USE ES to Industries '!$E$4 -> 7144 | E3: ='USE ES to Industries '!$Y$4 -> 32.764 | F3: ='USE ES to Industries '!$AS$4 -> 21590 | G3: ='USE ES to Industries '!$AV$4 -> 63979.28 | H3: 165855.72 | I3: ='USE ES to Industries '!$BD$4 -> 1.6565388 | J3: ='USE ES to Industries '!$BF$4 -> 14863657
A4: 1 | B4: Accommodation and food service activities | G4: 756.19515 | H4: 1567.738 | I4: 0.015670231 | J4: ='USE ES to Industries '!$BF$4 -> 14863657
A5: 2 | B5: Activities auxiliary to financial services and insurance activities | G5: 0 | H5: 1071.1566 | I5: 0.010706682
A6: 3 | B6: Activities of households as employers | G6: 0 | H6: 12.036847 | I6: 0.00012031359
A7: 4 | B7: Activities of membership organisations | G7: 389.11703 | H7: 806.71442 | I7: 0.0080634658
A8: 5 | B8: Advertising and market research | G8: 0 | H8: 323.9304 | I8: 0.0032378269
A9: 6 | B9: Air transport | G9: 44.31479 | H9: 91.87308 | I9: 0.00091831188
A10: 7 | B10: Aquaculture | G10: 572.85357 | H10: 1187.6356 | I10: 0.011870941
A11: 8 | B11: Architectural and engineering consultancy activities | G11: 0 | H11: 2840.1637 | I11: 0.028388687
A12: 9 | B12: Building of ships, oil platforms and moduls | G12: 289.36926 | H12: 599.91811 | I12: 0.0059964456
A13: 10 | B13: Computer programming and related activities | G13: 1756.3981 | H13: 3641.351 | I13: 0.036396907
A14: 11 | B14: Construction | G14: 4407.6035 | H14: 9137.8095 | I14: 0.091336429
A15: 12 | B15: Creative, arts and entertainment activities | G15: 336.824 | H15: 698.30091 | I15: 0.0069798251
A16: 13 | B16: Crop and animal production, hunting and related service activities | D16: ='USE ES to Industries '!$E$4 -> 7144 | E16: ='USE ES to Industries '!$Y$4 -> 32.764 | G16: 294.74075 | H16: 611.05424 | I16: 0.0061077562
A17: 14 | B17: Education | G17: 3651.9415 | H17: 7571.177 | I17: 0.075677247
A18: 15 | B18: Electricity, gas, steam and air conditioning supply | G18: 2350.6784 | H18: 4873.4083 | I18: 0.048711862
A19: 16 | B19: Employment activities | G19: 0 | H19: 1386.9396 | I19: 0.013863072
A20: 17 | B20: Fabricated metal products, except machinery and equipment | G20: 445.99163 | H20: 924.6264 | I20: 0.0092420479
A21: 18 | B21: Financial service activities, except insurance and pension funding | G21: 0 | H21: 5296.1719 | I21: 0.05293757
A22: 19 | B22: Fishing | G22: 304.89128 | H22: 632.09825 | I22: 0.0063181003
A23: 20 | B23: Forestry and logging | F23: ='USE ES to Industries '!$AS$4 -> 21590 | G23: 117.61982 | H23: 243.84851 | I23: 0.0024373733
A24: 21 | B24: Human health activities | G24: 3705.8539 | H24: 7682.9477 | I24: 0.076794445
A25: 22 | B25: Inland water transport and supply | G25: 86.062323 | H25: 178.42374 | I25: 0.0017834239
A26: 23 | B26: Insurance, except compulsory social security | G26: 0 | H26: 851.09518 | I26: 0.008507071
A27: 24 | B27: Land transport, except transport via pipelines | G27: 713.59845 | H27: 1479.4268 | I27: 0.014787522
A28: 25 | B28: Legal and accounting activities | G28: 0 | H28: 2583.7461 | I28: 0.02582568
A29: 26 | B29: Manufacture of basic metals | G29: 274.10396 | H29: 568.27021 | I29: 0.0056801109
A30: 27 | B30: Manufacture of computer, electronic and optical products | G30: 264.62486 | H30: 548.61821 | I30: 0.0054836806
A31: 28 | B31: Manufacture of electrical equipment | G31: 151.29038 | H31: 313.65404 | I31: 0.0031351102
A32: 29 | B32: Manufacture of food products, beverages and tobacco products | G32: 968.64547 | H32: 2008.1883 | I32: 0.020072726
A33: 30 | B33: Manufacture of furniture | G33: 168.4515 | H33: 349.23234 | I33: 0.003490731
A34: 31 | B34: Manufacture of machinery and equipment n.e.c. | G34: 368.421 | H34: 763.80757 | I34: 0.0076345929
A35: 32 | B35: Manufacture of motor vehicles, trailers and semi-trailers | G35: 63.983921 | H35: 132.65097 | I35: 0.0013259049
... A69: 66 | B69: Wholesale trade, except of motor vehicles | G69: 0 | H69: 4974.3705 | I69: 0.049721023

Sheet USE IND (A38) - ES (7) 
B2: Value chain analysis
B3: Reference year (2021) | C3: Ecosystem services | D3: Crop provision | E3: Pollination | F3: Wood provision | G3: Air filtration | H3: Flood control | I3: Local climate regulation | J3: Nature based tourism | K3: Global climate regulation
C4: Unit | D4: 1000 tonnes | E4: 1000 tonnes | F4: 1000 m3 | G4: tonnes PM2,5 | H4: ha | I4: degrees C | J4: overnight stays | K4: tonnes of storage | L4: tonnes of sequestration
C5: Total | D5: ='USE ES to Industries '!$E$4 -> 7144 | E5: ='USE ES to Industries '!$Y$4 -> 32.764 | F5: ='USE ES to Industries '!$AS$4 -> 21590 | G5: ='USE ES to Industries '!$AV$4 -> 63979.28 | H5: 165855.72 | I5: ='USE ES to Industries '!$BD$4 -> 1.6565388 | J5: ='USE ES to Industries '!$BF$4 -> 14863657
B6: Industries in the National Accounts (A64)
A7: 1 | B7: Accommodation and food service activities | G7: 756.19515 | H7: 1567.738 | I7: 0.015670231 | J7: ='USE ES to Industries '!$BF$4 -> 14863657
A8: 2 | B8: Activities auxiliary to financial services and insurance activities | G8: 0 | H8: 1071.1566 | I8: 0.010706682
A9: 3 | B9: Activities of households as employers | G9: 0 | H9: 12.036847 | I9: 0.00012031359
A10: 4 | B10: Activities of membership organisations | G10: 389.11703 | H10: 806.71442 | I10: 0.0080634658
A11: 5 | B11: Advertising and market research | G11: 0 | H11: 323.9304 | I11: 0.0032378269
A12: 6 | B12: Air transport | G12: 44.31479 | H12: 91.87308 | I12: 0.00091831188
A13: 7 | B13: Aquaculture | G13: 572.85357 | H13: 1187.6356 | I13: 0.011870941
A14: 8 | B14: Architectural and engineering consultancy activities | G14: 0 | H14: 2840.1637 | I14: 0.028388687
A15: 9 | B15: Building of ships, oil platforms and moduls | G15: 289.36926 | H15: 599.91811 | I15: 0.0059964456
A16: 10 | B16: Computer programming and related activities | G16: 1756.3981 | H16: 3641.351 | I16: 0.036396907
A17: 11 | B17: Construction | G17: 4407.6035 | H17: 9137.8095 | I17: 0.091336429
A18: 12 | B18: Creative, arts and entertainment activities | G18: 336.824 | H18: 698.30091 | I18: 0.0069798251
A19: 13 | B19: Crop and animal production, hunting and related service activities | D19: ='USE ES to Industries '!$E$4 -> 7144 | E19: ='USE ES to Industries '!$Y$4 -> 32.764 | G19: 294.74075 | H19: 611.05424 | I19: 0.0061077562
A20: 14 | B20: Education | G20: 3651.9415 | H20: 7571.177 | I20: 0.075677247
A21: 15 | B21: Electricity, gas, steam and air conditioning supply | G21: 2350.6784 | H21: 4873.4083 | I21: 0.048711862
A22: 16 | B22: Employment activities | G22: 0 | H22: 1386.9396 | I22: 0.013863072
A23: 17 | B23: Fabricated metal products, except machinery and equipment | G23: 445.99163 | H23: 924.6264 | I23: 0.0092420479
A24: 18 | B24: Financial service activities, except insurance and pension funding | G24: 0 | H24: 5296.1719 | I24: 0.05293757
A25: 19 | B25: Fishing | G25: 304.89128 | H25: 632.09825 | I25: 0.0063181003
A26: 20 | B26: Forestry and logging | F26: ='USE ES to Industries '!$AS$4 -> 21590 | G26: 117.61982 | H26: 243.84851 | I26: 0.0024373733
A27: 21 | B27: Human health activities | G27: 3705.8539 | H27: 7682.9477 | I27: 0.076794445
A28: 22 | B28: Inland water transport and supply | G28: 86.062323 | H28: 178.42374 | I28: 0.0017834239
A29: 23 | B29: Insurance, except compulsory social security | G29: 0 | H29: 851.09518 | I29: 0.008507071
A30: 24 | B30: Land transport, except transport via pipelines | G30: 713.59845 | H30: 1479.4268 | I30: 0.014787522
A31: 25 | B31: Legal and accounting activities | G31: 0 | H31: 2583.7461 | I31: 0.02582568
A32: 26 | B32: Manufacture of basic metals | G32: 274.10396 | H32: 568.27021 | I32: 0.0056801109
A33: 27 | B33: Manufacture of computer, electronic and optical products | G33: 264.62486 | H33: 548.61821 | I33: 0.0054836806
A34: 28 | B34: Manufacture of electrical equipment | G34: 151.29038 | H34: 313.65404 | I34: 0.0031351102
A35: 29 | B35: Manufacture of food products, beverages and tobacco products | G35: 968.64547 | H35: 2008.1883 | I35: 0.020072726
A36: 30 | B36: Manufacture of furniture | G36: 168.4515 | H36: 349.23234 | I36: 0.003490731
A37: 31 | B37: Manufacture of machinery and equipment n.e.c. | G37: 368.421 | H37: 763.80757 | I37: 0.0076345929
A38: 32 | B38: Manufacture of motor vehicles, trailers and semi-trailers | G38: 63.983921 | H38: 132.65097 | I38: 0.0013259049
... A72: 66 | B72: Wholesale trade, except of motor vehicles | G72: 0 | H72: 4974.3705 | I72: 0.049721023

Sheet ENCORE average
B1: Average rating by VA | C1: Ecosystem services | D1: Air filtration | E1: Flood control | F1: Local climate regulation | G1: Global climate regulation
C2: Unit | D2: tonnes PM2,5 | E2: ha | F2: degrees C | G2: tonnes of storage | H2: tonnes of sequestration
B3: Industries in the National Accounts (A64) | C3: Total | D3: 63979.28 | E3: 165855.72 | F3: 1.656538777 | G3: Column1 | H3: Column2
B4: Accommodation and food service activities | D4: 1.5 | E4: 1.5 | F4: 2
B5: Activities auxiliary to financial services and insurance activities | D5: 0 | E5: 1 | F5: 2
B6: Activities of households as employers | D6: 0 | E6: 1 | F6: 2
B7: Activities of membership organisations | D7: 0.14285714 | E7: 1 | F7: 2
B8: Advertising and market research | D8: 0 | E8: 1 | F8: 1.5
B9: Air transport | D9: 1 | E9: 1 | F9: 2
B10: Aquaculture | D10: 2.5 | E10: 3.5 | F10: 3.5
B11: Architectural and engineering consultancy activities | D11: 0 | E11: 1.5 | F11: 2
B12: Building of ships, oil platforms and moduls | D12: 1 | E12: 3 | F12: 2
B13: Computer programming and related activities | D13: 0.5 | E13: 1 | F13: 2
B14: Construction | D14: 0.85227273 | E14: 3.0643939 | F14: 2
B15: Creative, arts and entertainment activities | D15: 0.88888889 | E15: 1.8888889 | F15: 2
... B46: Other professional, scientific and technical activities | D46: 0.2 | E46: 1.4 | F46: 2
B47: Postal and courier activities | E47: 1 | F47: 2
B48: Printing and reproduction of recorded media | D48: 0 | E48: 3 | F48: 0
B49: Public administration and defence | D49: 0 | E49: 1 | F49: 2
B50: Publishing activities | D50: 0.5 | E50: 1 | F50: 2
B51: Real estate activities | D51: 1 | E51: 1 | F51: 2
B52: Refined petroleum, chemical and pharmaceutical products | D52: 1 | E52: 3 | F52: 2
B53: Rental and leasing activities | D53: 0 | E53: 2 | F53: 2
B54: Repair and installation of machinery and equipment | D54: 1 | E54: 3 | F54: 2
B55: Repair of computers and personal and household goods | D55: 0.5 | E55: 3 | F55: 2
B56: Retail trade, except of motor vehicles | D56: 1.1111111 | E56: 3 | F56: 2
B57: Scientific research and development | D57: 0.5 | E57: 1 | F57: 2
B58: Security and investigation activities | D58: 0.33333333 | E58: 1.2222222 | F58: 2.1111111
B59: Service activities incidental to oil and gas | D59: 1 | E59: 3.8333333 | F59: 1.9166667
... B69: Wholesale trade, except of motor vehicles | D69: 0 | E69: 2.1428571 | F69: 2

Sheet USE ES to Industries 
A1: GREEN -> COLOR TO INDUSTRIES | B1: BLUE COLOR ->TO HOUSEHOLDS | D1: Code | E1: PROV_CROP_MF11_12 | F1: PROV_CROP_MF11 | G1: PROV_CROP_MF111 | H1: PROV_CROP_MF112 | I1: PROV_CROP_MF113 | J1: PROV_CROP_MF114 | K1: PROV_CROP_MF115 | L1: PROV_CROP_MF116 | M1: PROV_CROP_MF117 | N1: PROV_CROP_MF118 | O1: PROV_CROP_MF119 | P1: PROV_CROP_MF11A | Q1: PROV_CROP_MF12 | R1: PROV_CROP_MF121 | S1: PROV_CROP_MF1211 | T1: PROV_CROP_MF1212 | U1: PROV_CROP_MF122 | V1: PROV_CROP_MF1221 | W1: PROV_CROP_MF1222 | Y1: PROV_POL_MF11_12 | Z1: PROV_POL_MF11 | AA1: PROV_POL_MF111 | AB1: PROV_POL_MF112 | AC1: PROV_POL_MF113 | AD1: PROV_POL_MF114 | AE1: PROV_POL_MF115 | AF1: PROV_POL_MF116 | AG1: PROV_POL_MF117 | AH1: PROV_POL_MF118 | AI1: PROV_POL_MF119 | AJ1: PROV_POL_MF11A | AL1: PROV_POL_MF12 | AM1: PROV_POL_MF121 | AN1: PROV_POL_MF1211 | AO1: PROV_POL_MF1212 | AP1: PROV_POL_MF122 | AQ1: PROV_POL_MF1221 | AR1: PROV_POL_MF1222 | AS1: PROV_WD_MF13MEMO | AT1: PROV_WD_MF13 | AU1: PROV_WD_TOTAL | AV1: REG_AIR_FILT_PM10 | AW1: REG_AIR_FILT_PM2_5 | AX1: REG_AIR_FILT_PEOPLE | AY1: REG_CO2_SEQ_NET | AZ1: REG_CO2_SEQ_PRIM | BA1: REG_CO2_STO_30CM | BB1: REG_CO2_STO_100CM | BC1: REG_CO2_STO_WHOLE | BD1: REG_COOL_TEMP_RED_25 | BE1: REG_COOL_PEOPLE | BF1: CULT_TOUR_NGT_SP | BG1: CULT_RECR_VISITS | BH1: REG_COOL_EXC_25 | BI1: REG_COOL_EXC_30 | BJ1: REG_COOL_EXC_35 | BK1: REG_COOL_UA_EXC_25 | BL1: REG_COOL_UA_EXC_30 | BM1: REG_COOL_UA_EXC_35 | BN1: REG_CO2_EMIS
D2: Description | E2: Crop provision: all MF1.1 and MF1.2 crops | F2: Crop provision: MF.1.1 Crops (excluding fodder crops) | G2: Crop provision: MF.1.1.1 Cereals | H2: Crop provision: MF.1.1.2 Roots, tubers | I2: Crop provision: MF.1.1.3 Sugar crops | J2: Crop provision: MF.1.1.4 Pulses | K2: Crop provision: MF.1.1.5 Nuts | L2: Crop provision: MF.1.1.6 Oil-bearing crops | M2: Crop provision: MF.1.1.7 Vegetables | N2: Crop provision: MF.1.1.8 Fruits | O2: Crop provision: MF.1.1.9 Fibres | P2: Crop provision: MF.1.1.A Other crops (excluding fodder crops) n.e.c. | Q2: Crop provision: MF.1.2 Crop residues (used), fodder crops and grazed biomass | R2: Crop provision: MF.1.2.1 Crop residues (used) | S2: Crop provision: MF.1.2.1.1 Straw | T2: Crop provision: MF.1.2.1.2 Other crop residues (sugar and fodder beet leaves, etc.) | U2: Crop provision: MF.1.2.2 Fodder crops and grazed biomass | V2: Crop provision: MF.1.2.2.1 Fodder crops (including biomass harvest from grassland) | W2: Crop provision: MF.1.2.2.2 Grazed biomass | X2: Total crop provision | Y2: Crop pollination: all MF1.1 and MF1.2 crops | Z2: Crop pollination: MF.1.1 Crops (excluding fodder crops) | AA2: Crop pollination: MF.1.1.1 Cereals | AB2: Crop pollination: MF.1.1.2 Roots, tubers | AC2: Crop pollination: MF.1.1.3 Sugar crops | AD2: Crop pollination: MF.1.1.4 Pulses | AE2: Crop pollination: MF.1.1.5 Nuts | AF2: Crop pollination: MF.1.1.6 Oil-bearing crops | AG2: Crop pollination: MF.1.1.7 Vegetables | AH2: Crop pollination: MF.1.1.8 Fruits | AI2: Crop pollination: MF.1.1.9 Fibres | AJ2: Crop pollination: MF.1.1.A Other crops (excluding fodder crops) n.e.c. | AK2: Total crop pollination | AL2: Crop pollination: MF.1.2 Crop residues (used), fodder crops and grazed biomass | AM2: Crop pollination: MF.1.2.1 Crop residues (used) | AN2: Crop pollination: MF.1.2.1.1 Straw | AO2: Crop pollination: MF.1.2.1.2 Other crop residues (sugar and fodder beet leaves, etc.) | AP2: Crop pollination: MF.1.2.2 Fodder crops and grazed biomass | AQ2: Crop pollination: MF.1.2.2.1 Fodder crops (including biomass harvest from grassland) | AR2: Crop pollination: MF.1.2.2.2 Grazed biomass | AS2: Wood provision: increment cultivated | AT2: Wood provision: removals non cultivated | AU2: Wood provision: total | AV2: Air filtration of PM10 | AW2: Air filtration of PM2.5 | AX2: Air filtration: benefitting people | AY2: Global climate regulation: net sequestration (indicator) | AZ2: Global climate sequestration: primary net sequestration (ecosystem service) | BA2: Global climate regulation: storage 30cm | BB2: Global climate regulation: storage 100cm | BC2: Global climate regulation: storage whole depth | BD2: Local climate regulation: cooling | BE2: Local climate regulation: benefitting people | BF2: Nature-based tourism: overnight stays | BG2: Nature-based recreation visits | BH2: Days with maximum temperature exceeding 25°C | BI2: Days with maximum temperature exceeding 30°C | BJ2: Days with maximum temperature exceeding 35°C | BK2: Urban area with an observed daily maximum temperature exceeding 25°C during summer | BL2: Urban area with an observed daily maximum temperature exceeding 30°C during summer | BM2: Urban area with an observed daily maximum temperature exceeding 35°C during summer | BN2: CO2 emissions from ecosystems
D3: UNIT | E3: 1000 tonnes | F3: 1000 tonnes | G3: 1000 tonnes | H3: 1000 tonnes | I3: 1000 tonnes | J3: 1000 tonnes | K3: 1000 tonnes | L3: 1000 tonnes | M3: 1000 tonnes | N3: 1000 tonnes | O3: 1000 tonnes | P3: 1000 tonnes | Q3: 1000 tonnes | R3: 1000 tonnes | S3: 1000 tonnes | T3: 1000 tonnes | U3: 1000 tonnes | V3: 1000 tonnes | W3: 1000 tonnes | X3: 1000 tonnes | Y3: 1000 tonnes | Z3: 1000 tonnes | AA3: 1000 tonnes | AB3: 1000 tonnes | AC3: 1000 tonnes | AD3: 1000 tonnes | AE3: 1000 tonnes | AF3: 1000 tonnes | AG3: 1000 tonnes | AH3: 1000 tonnes | AI3: 1000 tonnes | AJ3: 1000 tonnes | AK3: 1000 tonnes | AL3: 1000 tonnes | AM3: 1000 tonnes | AN3: 1000 tonnes | AO3: 1000 tonnes | AP3: 1000 tonnes | AQ3: 1000 tonnes | AR3: 1000 tonnes | AS3: 1000 m3 | AT3: 1000 m3 | AV3: tonnes | AW3: tonnes | AX3: tonnes | BD3: degrees C | BE3: degrees C | BF3: overnight stays
D4: TOTAL REPORTED TO EUROSTAT | E4: 7144 | F4: 1787 | G4: 1124 | H4: 369 | I4: 0 | J4: 4 | K4: 0 | L4: 7 | M4: 203 | N4: 32 | O4: 0 | P4: 48 | Q4: 5357 | R4: 34 | S4: 34 | T4: 0 | U4: 5323 | V4: 4120 | W4: 1203 | X4: =SUM(E4:W4) -> 26789 | Y4: 32.764 | Z4: 32.764 | AA4: 0 | AB4: 0 | AC4: 0 | AD4: 0.153 | AE4: 0 | AF4: 0 | AG4: 14.7385 | AH4: 17.8725 | AI4: 0 | AJ4: 0 | AK4: =SUM(Y4:AJ4) -> 98.292 | AS4: 21590 | AV4: 63979.28 | AW4: 43031.88 | AX4: =AV4+AW4 -> 107011.16 | BD4: 1.6565388 | BE4: 1.6565388 | BF4: 14863657
A5: Industries in the National Accounts (A38) | B5: Industries in the National Accounts (A64) | C5: NACE rev. 2
A6: Agriculture, forestry and fishing | B6: Crop and animal production, hunting and related service activities | C6: 0.1
B7: Forestry and logging | C7: 0.2
B8: Fishing | C8: 03-1
B9: Aquaculture | C9: 03-2
A10: Mining and quarrying | B10: Mining and quarrying | C10: 05 + 07 + 08 + 09.09
B11: Oil and gas extraction | C11: 6
B12: Service activities incidental to oil and gas | C12: 05+07+08+09.09
A13: Manufacture of food products, beverages and tobacco products | B13: Manufacture of food products, beverages and tobacco products | C13: 10 + 11 + 12
A14: Manufacture of textiles, wearing apparel and leather products | B14: Manufacture of textiles, wearing apparel and leather products | C14: 13 + 14 + 15
A15: Manufacture of wood and paper products, and printing | B15: Manufacture of wood and wood products, except furniture | C15: 16
B16: Manufacture of paper and paper products | C16: 17
B17: Printing and reproduction of recorded media | C17: 18
A18: Refined petroleum, chemical and pharmaceutical products | B18: Refined petroleum, chemical and pharmaceutical products | C18: 19 + 20 + 21
A19: Manufacture of rubber and plastic products, and other non-metalic mineral products | B19: Manufacture of rubber and plastic products | C19: 22
B20: Manufacture of other non-metallic mineral products | C20: 23
A21: Manufacture of basic metals and fabricated metal products, except machinery and equipment | B21: Manufacture of basic metals | C21: 24
B22: Fabricated metal products, except machinery and equipment | C22: 25
A23: Manufacture of computer, electronic and optical products | B23: Manufacture of computer, electronic and optical products | C23: 26
A24: Manufacture of electrical equipment | B24: Manufacture of electrical equipment | C24: 27
A25: Manufacture of machinery and equipment n.e.c. | B25: Manufacture of machinery and equipment n.e.c. | C25: 28
A26: Manufacture of transport equipment | B26: Manufacture of motor vehicles, trailers and semi-trailers | C26: 29
B27: Building of ships, oil platforms and moduls | C27: 30
A28: Manufacture of furniture | B28: Manufacture of furniture | C28: 31 +32
B29: Repair and installation of machinery and equipment | C29: 33
A30: Electricity, gas, steam and air-conditioning supply | B30: Electricity, gas, steam and air conditioning supply | C30: 35
A31: Water supply | B31: Water collection, treatment and supply | C31: 36
B32: Sewerage | C32: 37 +38 + 39
A33: Construction | B33: Construction | C33: 41 + 42 + 43
A34: Wholesale and retail trade, repair of motor vehicles and motorcycles | B34: Wholesale and retail trade and repair of motor vehicles | C34: 45
B35: Wholesale trade, except of motor vehicles | C35: 46
B36: Retail trade, except of motor vehicles | C36: 47
A37: Tranport and storage | B37: Land transport, except transport via pipelines | C37: 49.5
B38: Transport via pipelines | C38: 50.101 + 50.201
B39: Ocean transport | C39: 49.1 + 49.2 + 49.3 + 49.4
B40: Inland water transport and supply | C40: 50.102 + 50.202 + 50.109 + 50.3 + 50.4 + 50.203 + 50.204
...

Sheet SUPPLY ES from Ecosystems
E6: ECO01 | F6: ECO02 | G6: ECO03 | H6: ECO04 | I6: ECO05 | J6: ECO06 | K6: ECO07 | L6: ECO08 | M6: ECO09 | N6: ECO10 | O6: ECO11 | P6: ECO12 | Q6: TOTAL
E7: 1. Settlements and other artificial areas | F7: 2. Cropland | G7: 3. Grassland | H7: 4. Forest and woodlands | I7: 5. Heathlands and shrub | J7: 6. Sparsely vegetated ecosystems | K7: 7. Inland wetlands | L7: 8. Rivers and canals | M7: 9. Lakes and reservoirs | N7: 10. Marine inlets and transitional waters | O7: 11. Coastal beaches, dunes and wetlands | P7: 12. Marine ecosystems | Q7: Total across ecosystems
